Workbook

Sheet Sheet1
A1: {
A2: "associates":{
A3: "0":{
A4: "201710007" | B4: :{ | C4: "NAME": "ANGELINA SPINHARDI SARAGIOTTO" | D4: ,"COURSE":" | E4: Administração | F4: " | G4: },
A5: "201810008" | B5: :{ | C5: "NAME": "ANNA CAROLINA MARCOS DOS SANTOS" | D5: ,"COURSE":" | E5: Administração | F5: " | G5: },
A6: "201412017" | B6: :{ | C6: "NAME": "ARIANA SERAFIM SILVA" | D6: ,"COURSE":" | E6: Administração | F6: " | G6: },
A7: "201710741" | B7: :{ | C7: "NAME": "ARTHUR DE CAMPOS FORLEVIZE" | D7: ,"COURSE":" | E7: Administração | F7: " | G7: },
A8: "201810009" | B8: :{ | C8: "NAME": "AUGUSTO BRUNI NARDELLI" | D8: ,"COURSE":" | E8: Administração | F8: " | G8: },
A9: "201610450" | B9: :{ | C9: "NAME": "BEATRIZ FREDERICO" | D9: ,"COURSE":" | E9: Administração | F9: " | G9: },
A10: "201610016" | B10: :{ | C10: "NAME": "BRUNA PEREZ RICCI" | D10: ,"COURSE":" | E10: Administração | F10: " | G10: },
A11: "201511217" | B11: :{ | C11: "NAME": "CAIO AUGUSTO PALUMBO MARCHI" | D11: ,"COURSE":" | E11: Administração | F11: " | G11: },
A12: "201610022" | B12: :{ | C12: "NAME": "CAROLINA DE GRANDI SAMPAIO ANDRADE FONSE" | D12: ,"COURSE":" | E12: Administração | F12: " | G12: },
A13: "201512008" | B13: :{ | C13: "NAME": "CAROLINE DE OLIVEIRA BRANDAO" | D13: ,"COURSE":" | E13: Administração | F13: " | G13: },
A14: "201512016" | B14: :{ | C14: "NAME": "COBI JOHNNES DA SILVA NASCIMENTO" | D14: ,"COURSE":" | E14: Administração | F14: " | G14: },
A15: "201715012" | B15: :{ | C15: "NAME": "DIOGO MARIANO SILVA" | D15: ,"COURSE":" | E15: Administração | F15: " | G15: },
... A130: "201710149" | B130: :{ | C130: "NAME": "VINICIUS MEIRELES NOGUEIRA" | D130: ,"COURSE":" | E130: Economia | F130: " | G130: }},
A131: "1":{
A132: "201710152" | B132: :{ | C132: "NAME": "ALANA DA GRACA SANTOS CREMASCO" | D132: ,"COURSE":" | E132: Direito | F132: " | G132: },
A133: "201810142" | B133: :{ | C133: "NAME": "ALEXANDRE CRUZ DE ANTONIO" | D133: ,"COURSE":" | E133: Direito | F133: " | G133: },
A134: "201740097" | B134: :{ | C134: "NAME": "AMANDA CORRAL FURLAN" | D134: ,"COURSE":" | E134: Direito | F134: " | G134: },
A135: "201710153" | B135: :{ | C135: "NAME": "AMANDA CUNHA JARDINI" | D135: ,"COURSE":" | E135: Direito | F135: " | G135: },
A136: "201710157" | B136: :{ | C136: "NAME": "ANA CAROLINA BUENO MENEGUELLI" | D136: ,"COURSE":" | E136: Direito | F136: " | G136: },
A137: "201710161" | B137: :{ | C137: "NAME": "ANA JULIA BIANCO FRATTI" | D137: ,"COURSE":" | E137: Direito | F137: " | G137: },
A138: "201511211" | B138: :{ | C138: "NAME": "ANA JULIA FERREIRA LOURENCO" | D138: ,"COURSE":" | E138: Direito | F138: " | G138: },
A139: "201610185" | B139: :{ | C139: "NAME": "ANA LAURA LOMBARDI CASSIANO RIBEIRO DA C" | D139: ,"COURSE":" | E139: Direito | F139: " | G139: },
A140: "201610186" | B140: :{ | C140: "NAME": "ANA LAURA MONTAGNOLLI DAMHA" | D140: ,"COURSE":" | E140: Direito | F140: " | G140: },
A141: "201610193" | B141: :{ | C141: "NAME": "ANNA CAROLINA BARBOSA ALMEIDA MENDONCA" | D141: ,"COURSE":" | E141: Direito | F141: " | G141: },
A142: "201610194" | B142: :{ | C142: "NAME": "ANNA MARIA RIZZO E ZOCCHIO" | D142: ,"COURSE":" | E142: Direito | F142: " | G142: },
A143: "201512035" | B143: :{ | C143: "NAME": "ANTONIO SESTITO NETO" | D143: ,"COURSE":" | E143: Direito | F143: " | G143: },
... A286: "201310502" | B286: :{ | C286: "NAME": "YASMIN D`AGOSTINI" | D286: ,"COURSE":" | E286: Direito | F286: " | G286: }},
A287: "2":{
A288: "201610586" | B288: :{ | C288: "NAME": "ANDRE GARCIA DOBERMANN" | D288: ,"COURSE":" | E288: Eng. Computação | F288: " | G288: },
A289: "201610671" | B289: :{ | C289: "NAME": "ANDRE MONTEIRO TELLA" | D289: ,"COURSE":" | E289: Eng. Computação | F289: " | G289: },
A290: "201610670" | B290: :{ | C290: "NAME": "ANDRE SCATTOLIN" | D290: ,"COURSE":" | E290: Eng. Computação | F290: " | G290: },
A291: "201710629" | B291: :{ | C291: "NAME": "BRIAN AMADEUS BENKO BRENNINKMEIJER" | D291: ,"COURSE":" | E291: Eng. Computação | F291: " | G291: },
A292: "201840048" | B292: :{ | C292: "NAME": "BRUNO ARRIVABENE SANSANA" | D292: ,"COURSE":" | E292: Eng. Computação | F292: " | G292: },
A293: "201610675" | B293: :{ | C293: "NAME": "CAIO RAFFI DE ALMEIDA" | D293: ,"COURSE":" | E293: Eng. Computação | F293: " | G293: },
A294: "201612004" | B294: :{ | C294: "NAME": "DANIEL ELVIS QUEVEDO" | D294: ,"COURSE":" | E294: Eng. Computação | F294: " | G294: },
A295: "201511004" | B295: :{ | C295: "NAME": "ESTEVAO FRANCISCO FAY" | D295: ,"COURSE":" | E295: Eng. Computação | F295: " | G295: },
A296: "201650014" | B296: :{ | C296: "NAME": "FABIO DE OLIVEIRA ROCHA" | D296: ,"COURSE":" | E296: Eng. Computação | F296: " | G296: },
...

Sheet Sheet5
A1: =CONCATENATE(Sheet1!A1,Sheet1!B1,Sheet1!C1,Sheet1!D1,Sheet1!E1,Sheet1!F1,Sheet1!G1) -> {
A2: =CONCATENATE(Sheet1!A2,Sheet1!B2,Sheet1!C2,Sheet1!D2,Sheet1!E2,Sheet1!F2,Sheet1!G2) -> "associates":{
A3: =CONCATENATE(Sheet1!A3,Sheet1!B3,Sheet1!C3,Sheet1!D3,Sheet1!E3,Sheet1!F3,Sheet1!G3) -> "0":{
A4: =CONCATENATE(Sheet1!A4,Sheet1!B4,Sheet1!C4,Sheet1!D4,Sheet1!E4,Sheet1!F4,Sheet1!G4) -> "201710007":{ "NAME": "ANGELINA SPINHARDI SARAGIOTTO","COURSE":"Administração"},
A5: =CONCATENATE(Sheet1!A5,Sheet1!B5,Sheet1!C5,Sheet1!D5,Sheet1!E5,Sheet1!F5,Sheet1!G5) -> "201810008":{ "NAME": "ANNA CAROLINA MARCOS DOS SANTOS","COURSE":"Administração"},
A6: =CONCATENATE(Sheet1!A6,Sheet1!B6,Sheet1!C6,Sheet1!D6,Sheet1!E6,Sheet1!F6,Sheet1!G6) -> "201412017":{ "NAME": "ARIANA SERAFIM SILVA","COURSE":"Administração"},
A7: =CONCATENATE(Sheet1!A7,Sheet1!B7,Sheet1!C7,Sheet1!D7,Sheet1!E7,Sheet1!F7,Sheet1!G7) -> "201710741":{ "NAME": "ARTHUR DE CAMPOS FORLEVIZE","COURSE":"Administração"},
A8: =CONCATENATE(Sheet1!A8,Sheet1!B8,Sheet1!C8,Sheet1!D8,Sheet1!E8,Sheet1!F8,Sheet1!G8) -> "201810009":{ "NAME": "AUGUSTO BRUNI NARDELLI","COURSE":"Administração"},
A9: =CONCATENATE(Sheet1!A9,Sheet1!B9,Sheet1!C9,Sheet1!D9,Sheet1!E9,Sheet1!F9,Sheet1!G9) -> "201610450":{ "NAME": "BEATRIZ FREDERICO","COURSE":"Administração"},
A10: =CONCATENATE(Sheet1!A10,Sheet1!B10,Sheet1!C10,Sheet1!D10,Sheet1!E10,Sheet1!F10,Sheet1!G10) -> "201610016":{ "NAME": "BRUNA PEREZ RICCI","COURSE":"Administração"}, | G10: =CONCATENATE(Sheet1!B2,Sheet1!C2,Sheet1!D2,Sheet1!E2,Sheet1!F3,Sheet1!G3)
A11: =CONCATENATE(Sheet1!A11,Sheet1!B11,Sheet1!C11,Sheet1!D11,Sheet1!E11,Sheet1!F11,Sheet1!G11) -> "201511217":{ "NAME": "CAIO AUGUSTO PALUMBO MARCHI","COURSE":"Administração"},
A12: =CONCATENATE(Sheet1!A12,Sheet1!B12,Sheet1!C12,Sheet1!D12,Sheet1!E12,Sheet1!F12,Sheet1!G12) -> "201610022":{ "NAME": "CAROLINA DE GRANDI SAMPAIO ANDRADE FONSE","COURSE":"Administração"},
A13: =CONCATENATE(Sheet1!A13,Sheet1!B13,Sheet1!C13,Sheet1!D13,Sheet1!E13,Sheet1!F13,Sheet1!G13) -> "201512008":{ "NAME": "CAROLINE DE OLIVEIRA BRANDAO","COURSE":"Administração"},
A14: =CONCATENATE(Sheet1!A14,Sheet1!B14,Sheet1!C14,Sheet1!D14,Sheet1!E14,Sheet1!F14,Sheet1!G14) -> "201512016":{ "NAME": "COBI JOHNNES DA SILVA NASCIMENTO","COURSE":"Administração"},
A15: =CONCATENATE(Sheet1!A15,Sheet1!B15,Sheet1!C15,Sheet1!D15,Sheet1!E15,Sheet1!F15,Sheet1!G15) -> "201715012":{ "NAME": "DIOGO MARIANO SILVA","COURSE":"Administração"},
A16: =CONCATENATE(Sheet1!A16,Sheet1!B16,Sheet1!C16,Sheet1!D16,Sheet1!E16,Sheet1!F16,Sheet1!G16) -> "201810016":{ "NAME": "EDUARDO LUIZ JURDIM","COURSE":"Administração"},
A17: =CONCATENATE(Sheet1!A17,Sheet1!B17,Sheet1!C17,Sheet1!D17,Sheet1!E17,Sheet1!F17,Sheet1!G17) -> "201710744":{ "NAME": "ELIANA PEREIRA RIGONI","COURSE":"Administração"},
A18: =CONCATENATE(Sheet1!A18,Sheet1!B18,Sheet1!C18,Sheet1!D18,Sheet1!E18,Sheet1!F18,Sheet1!G18) -> "201710012":{ "NAME": "ELIAS DONATO DE CARVALHO JUNIOR","COURSE":"Administração"},
A19: =CONCATENATE(Sheet1!A19,Sheet1!B19,Sheet1!C19,Sheet1!D19,Sheet1!E19,Sheet1!F19,Sheet1!G19) -> "201610028":{ "NAME": "ELMER HENRIQUE GAMBARDELLA","COURSE":"Administração"},
A20: =CONCATENATE(Sheet1!A20,Sheet1!B20,Sheet1!C20,Sheet1!D20,Sheet1!E20,Sheet1!F20,Sheet1!G20) -> "201510486":{ "NAME": "FELIPE JOSE PIERRO RESTANI","COURSE":"Administração"},
A21: =CONCATENATE(Sheet1!A21,Sheet1!B21,Sheet1!C21,Sheet1!D21,Sheet1!E21,Sheet1!F21,Sheet1!G21) -> "201610031":{ "NAME": "FELIPE OTTONI BUFFONI","COURSE":"Administração"},
A22: =CONCATENATE(Sheet1!A22,Sheet1!B22,Sheet1!C22,Sheet1!D22,Sheet1!E22,Sheet1!F22,Sheet1!G22) -> "201510035":{ "NAME": "FERNANDO HOMEM DE MELLO PEREZ GARCIA","COURSE":"Administração"},
... A794: =CONCATENATE(Sheet1!A794,Sheet1!B794,Sheet1!C794,Sheet1!D794,Sheet1!E794,Sheet1!F794,Sheet1!G794) -> }}}
